<?xml version="1.0" encoding="utf-8"?>


<robot
  name="manipulator_urdf">
  <link
    name="base_link">
    <inertial>
      <origin
        xyz="-0.00044497 0.0014075 0.011411"
        rpy="0 0 0" />
      <mass
        value="0.042631" />
      <inertia
        ixx="2.6758E-05"
        ixy="-6.522E-07"
        ixz="2.4559E-08"
        iyy="2.5173E-05"
        iyz="6.9831E-08"
        izz="4.522E-05" />
    </inertial>
    <visual>
      <origin
        xyz="0 0 0"
        rpy="0 0 0" />
      <geometry>
        <mesh
          filename="package://manipulator_urdf/meshes/base_link.STL" />
      </geometry>
      <material
        name="">
        <color
          rgba="0.79216 0.81961 0.93333 1" />
      </material>
    </visual>
    <collision>
      <origin
        xyz="0 0 0"
        rpy="0 0 0" />
      <geometry>
        <mesh
          filename="package://manipulator_urdf/meshes/base_link.STL" />
      </geometry>
    </collision>
  </link>
  <link
    name="base_plate">
    <inertial>
      <origin
        xyz="-0.0016083 0.0017587 0.012046"
        rpy="0 0 0" />
      <mass
        value="0.043625" />
      <inertia
        ixx="1.5463E-05"
        ixy="1.5928E-06"
        ixz="1.1037E-06"
        iyy="1.9044E-05"
        iyz="-1.4228E-06"
        izz="2.5484E-05" />
    </inertial>
    <visual>
      <origin
        xyz="0 0 0"
        rpy="0 0 0" />
      <geometry>
        <mesh
          filename="package://manipulator_urdf/meshes/base_plate.STL" />
      </geometry>
      <material
        name="">
        <color
          rgba="0.75294 0.75294 0.75294 1" />
      </material>
    </visual>
    <collision>
      <origin
        xyz="0 0 0"
        rpy="0 0 0" />
      <geometry>
        <mesh
          filename="package://manipulator_urdf/meshes/base_plate.STL" />
      </geometry>
    </collision>
  </link>
  <joint
    name="base_link_to_base_plate"
    type="revolute">
    <origin
      xyz="0 0 0.031"
      rpy="0 0 0" />
    <parent
      link="base_link" />
    <child
      link="base_plate" />
    <axis
      xyz="0 0 1" />
    <limit
      lower="-1.5708"
      upper="1.5708"
      effort="30"
      velocity="10" />
  </joint>
  <link
    name="forward_drive_arm_Link">
    <inertial>
      <origin
        xyz="-0.0046735 0.0051251 0.033408"
        rpy="0 0 0" />
      <mass
        value="0.013063" />
      <inertia
        ixx="9.3913E-06"
        ixy="2.2846E-08"
        ixz="1.4619E-07"
        iyy="9.8356E-06"
        iyz="-1.3557E-06"
        izz="1.2317E-06" />
    </inertial>
    <visual>
      <origin
        xyz="0 0 0"
        rpy="0 0 0" />
      <geometry>
        <mesh
          filename="package://manipulator_urdf/meshes/forward_drive_arm_Link.STL" />
      </geometry>
      <material
        name="">
        <color
          rgba="0.79216 0.81961 0.93333 1" />
      </material>
    </visual>
    <collision>
      <origin
        xyz="0 0 0"
        rpy="0 0 0" />
      <geometry>
        <mesh
          filename="package://manipulator_urdf/meshes/forward_drive_arm_Link.STL" />
      </geometry>
    </collision>
  </link>
  <joint
    name="base_plate_to_forward_drive_arm"
    type="revolute">
    <origin
      xyz="0 0 0.0349"
      rpy="0 0 0" />
    <parent
      link="base_plate" />
    <child
      link="forward_drive_arm_Link" />
    <axis
      xyz="1 0 0" />
    <limit
      lower="-1.5708"
      upper="1.5708"
      effort="30"
      velocity="10" />
  </joint>
  <link
    name="horizontal_arm_Link">
    <inertial>
      <origin
        xyz="-0.0022984 -0.051724 0.0036581"
        rpy="0 0 0" />
      <mass
        value="0.0087562" />
      <inertia
        ixx="1.1998E-05"
        ixy="4.2849E-10"
        ixz="-2.1998E-11"
        iyy="2.2054E-07"
        iyz="6.0377E-07"
        izz="1.1857E-05" />
    </inertial>
    <visual>
      <origin
        xyz="0 0 0"
        rpy="0 0 0" />
      <geometry>
        <mesh
          filename="package://manipulator_urdf/meshes/horizontal_arm_Link.STL" />
      </geometry>
      <material
        name="">
        <color
          rgba="0.79216 0.81961 0.93333 1" />
      </material>
    </visual>
    <collision>
      <origin
        xyz="0 0 0"
        rpy="0 0 0" />
      <geometry>
        <mesh
          filename="package://manipulator_urdf/meshes/horizontal_arm_Link.STL" />
      </geometry>
    </collision>
  </link>
  <joint
    name="forward_drive_armto_horizontal_arm"
    type="revolute">
    <origin
      xyz="0 0.012165 0.07907"
      rpy="0 0 0" />
    <parent
      link="forward_drive_arm_Link" />
    <child
      link="horizontal_arm_Link" />
    <axis
      xyz="-1 0 0" />
    <limit
      lower="-1.5708"
      upper="1.5708"
      effort="30"
      velocity="10" />
  </joint>
  <link
    name="claw_support_Link">
    <inertial>
      <origin
        xyz="-0.0033141 -0.013342 -0.0049958"
        rpy="0 0 0" />
      <mass
        value="0.0066694" />
      <inertia
        ixx="2.254E-06"
        ixy="4.0671E-08"
        ixz="1.2764E-07"
        iyy="1.1079E-06"
        iyz="-3.6729E-07"
        izz="1.7502E-06" />
    </inertial>
    <visual>
      <origin
        xyz="0 0 0"
        rpy="0 0 0" />
      <geometry>
        <mesh
          filename="package://manipulator_urdf/meshes/claw_support_Link.STL" />
      </geometry>
      <material
        name="">
        <color
          rgba="0.79216 0.81961 0.93333 1" />
      </material>
    </visual>
    <collision>
      <origin
        xyz="0 0 0"
        rpy="0 0 0" />
      <geometry>
        <mesh
          filename="package://manipulator_urdf/meshes/claw_support_Link.STL" />
      </geometry>
    </collision>
  </link>
  <joint
    name="horizontal_arm_to_claw_support"
    type="fixed">
    <origin
      xyz="0 -0.11477 0.0071825"
      rpy="0 0 0" />
    <parent
      link="horizontal_arm_Link" />
    <child
      link="claw_support_Link" />
    <axis
      xyz="1 0 0" />
    <limit
      lower="0"
      upper="0"
      effort="0"
      velocity="0" />
  </joint>
  <link
    name="gripper_right_Link">
    <inertial>
      <origin
        xyz="0.0023939 -0.018367 -0.0069277"
        rpy="0 0 0" />
      <mass
        value="0.0014646" />
      <inertia
        ixx="4.3292E-07"
        ixy="3.2675E-08"
        ixz="-3.933E-09"
        iyy="2.4067E-08"
        iyz="1.7241E-08"
        izz="4.4796E-07" />
    </inertial>
    <visual>
      <origin
        xyz="0 0 0"
        rpy="0 0 0" />
      <geometry>
        <mesh
          filename="package://manipulator_urdf/meshes/gripper_right_Link.STL" />
      </geometry>
      <material
        name="">
        <color
          rgba="0.79216 0.81961 0.93333 1" />
      </material>
    </visual>
    <collision>
      <origin
        xyz="0 0 0"
        rpy="0 0 0" />
      <geometry>
        <mesh
          filename="package://manipulator_urdf/meshes/gripper_right_Link.STL" />
      </geometry>
    </collision>
  </link>
  <joint
    name="claw_support_to_gripper_right"
    type="revolute">
    <origin
      xyz="-0.0113 -0.014515 -0.0091654"
      rpy="0 0 0" />
    <parent
      link="claw_support_Link" />
    <child
      link="gripper_right_Link" />
    <axis
      xyz="0 0 1" />
    <limit
      lower="-1.57079632679"
      upper="0"
      effort="30"
      velocity="10" />
  </joint>
  <link
    name="gripper_left_Link">
    <inertial>
      <origin
        xyz="-0.0021875 -0.019421 -0.0068857"
        rpy="0 0 0" />
      <mass
        value="0.0013895" />
      <inertia
        ixx="4.0273E-07"
        ixy="-2.1282E-08"
        ixz="3.4894E-09"
        iyy="2.2299E-08"
        iyz="1.6148E-08"
        izz="4.1619E-07" />
    </inertial>
    <visual>
      <origin
        xyz="0 0 0"
        rpy="0 0 0" />
      <geometry>
        <mesh
          filename="package://manipulator_urdf/meshes/gripper_left_Link.STL" />
      </geometry>
      <material
        name="">
        <color
          rgba="0.79216 0.81961 0.93333 1" />
      </material>
    </visual>
    <collision>
      <origin
        xyz="0 0 0"
        rpy="0 0 0" />
      <geometry>
        <mesh
          filename="package://manipulator_urdf/meshes/gripper_left_Link.STL" />
      </geometry>
    </collision>
  </link>
  <joint
    name="claw_support_to_gripper_left"
    type="revolute">
    <origin
      xyz="0.0068024 -0.014517 -0.0093651"
      rpy="0 0 0" />
    <parent
      link="claw_support_Link" />
    <child
      link="gripper_left_Link" />
    <axis
      xyz="0 0 1" />
    <limit
      lower="0"
      upper="1.57079632679"
      effort="30"
      velocity="10" />
    <mimic
      joint="claw_support_to_gripper_right"
      multiplier="-1"
      offset="0" />
  </joint>
</robot>